Workbook

Sheet unicode
A1: Bopomofo | B1: GB2312 code | C1: Letter
A2: ㄅ | B2: 3105 | C2: B
A3: ㄆ | B3: 3106 | C3: P
A4: ㄇ | B4: 3107 | C4: M
A5: ㄈ | B5: 3108 | C5: F
A6: ㄉ | B6: 3109 | C6: D
A7: ㄊ | B7: 310A | C7: T
A8: ㄋ | B8: 310B | C8: N
A9: ㄌ | B9: 310C | C9: L
A10: ㄍ | B10: 310D | C10: G
A11: ㄎ | B11: 310E | C11: K
A12: ㄏ | B12: 310F | C12: H
A13: ㄐ | B13: 3110 | C13: J
A14: ㄑ | B14: 3111 | C14: Q
A15: ㄒ | B15: 3112 | C15: X
A16: ㄓ | B16: 3113 | C16: ZH
A17: ㄔ | B17: 3114 | C17: CH
A18: ㄕ | B18: 3115 | C18: SH
A19: ㄖ | B19: 3116 | C19: R
A20: ㄗ | B20: 3117 | C20: Z
A21: ㄘ | B21: 3118 | C21: C
A22: ㄙ | B22: 3119 | C22: S
A23: ㄚ | B23: 311A | C23: A
A24: ㄛ | B24: 311B | C24: O
A25: ㄜ | B25: 311C | C25: E
A26: ㄝ | B26: 311D | C26: EH
A27: ㄞ | B27: 311E | C27: AI
A28: ㄟ | B28: 311F | C28: EI
A29: ㄠ | B29: 3120 | C29: AU
A30: ㄡ | B30: 3121 | C30: OU
A31: ㄢ | B31: 3122 | C31: AN
A32: ㄣ | B32: 3123 | C32: EN
A33: ㄤ | B33: 3124 | C33: ANG
A34: ㄥ | B34: 3125 | C34: ENG
A35: ㄦ | B35: 3126 | C35: ER
A36: ㄧ | B36: 3127 | C36: I
A37: ㄨ | B37: 3128 | C37: U
A38: ㄩ | B38: 3129 | C38: IU
A39: ㄪ | B39: 312A | C39: V
A40: ㄫ | B40: 312B | C40: NG
...

Sheet 4csv
A1: ," | B1: =unicode!B2 -> 3105 | C1: "," | D1: =unicode!A2 -> ㄅ | E1: " | F1: ,,"ai@indexbox.com","1","GB2312","注音","unicode",NULL,NULL | G1: =A1&B1&C1&D1&E1&F1 -> ,"3105","ㄅ",,"ai@indexbox.com","1","GB2312","注音","unicode",NULL,NULL
A2: ," | B2: =unicode!B3 -> 3106 | C2: "," | D2: =unicode!A3 -> ㄆ | E2: " | F2: ,,"ai@indexbox.com","1","GB2312","注音","unicode",NULL,NULL | G2: =A2&B2&C2&D2&E2&F2 -> ,"3106","ㄆ",,"ai@indexbox.com","1","GB2312","注音","unicode",NULL,NULL
A3: ," | B3: =unicode!B4 -> 3107 | C3: "," | D3: =unicode!A4 -> ㄇ | E3: " | F3: ,,"ai@indexbox.com","1","GB2312","注音","unicode",NULL,NULL | G3: =A3&B3&C3&D3&E3&F3 -> ,"3107","ㄇ",,"ai@indexbox.com","1","GB2312","注音","unicode",NULL,NULL
A4: ," | B4: =unicode!B5 -> 3108 | C4: "," | D4: =unicode!A5 -> ㄈ | E4: " | F4: ,,"ai@indexbox.com","1","GB2312","注音","unicode",NULL,NULL | G4: =A4&B4&C4&D4&E4&F4 -> ,"3108","ㄈ",,"ai@indexbox.com","1","GB2312","注音","unicode",NULL,NULL
A5: ," | B5: =unicode!B6 -> 3109 | C5: "," | D5: =unicode!A6 -> ㄉ | E5: " | F5: ,,"ai@indexbox.com","1","GB2312","注音","unicode",NULL,NULL | G5: =A5&B5&C5&D5&E5&F5 -> ,"3109","ㄉ",,"ai@indexbox.com","1","GB2312","注音","unicode",NULL,NULL
A6: ," | B6: =unicode!B7 -> 310A | C6: "," | D6: =unicode!A7 -> ㄊ | E6: " | F6: ,,"ai@indexbox.com","1","GB2312","注音","unicode",NULL,NULL | G6: =A6&B6&C6&D6&E6&F6 -> ,"310A","ㄊ",,"ai@indexbox.com","1","GB2312","注音","unicode",NULL,NULL
A7: ," | B7: =unicode!B8 -> 310B | C7: "," | D7: =unicode!A8 -> ㄋ | E7: " | F7: ,,"ai@indexbox.com","1","GB2312","注音","unicode",NULL,NULL | G7: =A7&B7&C7&D7&E7&F7 -> ,"310B","ㄋ",,"ai@indexbox.com","1","GB2312","注音","unicode",NULL,NULL
A8: ," | B8: =unicode!B9 -> 310C | C8: "," | D8: =unicode!A9 -> ㄌ | E8: " | F8: ,,"ai@indexbox.com","1","GB2312","注音","unicode",NULL,NULL | G8: =A8&B8&C8&D8&E8&F8 -> ,"310C","ㄌ",,"ai@indexbox.com","1","GB2312","注音","unicode",NULL,NULL
A9: ," | B9: =unicode!B10 -> 310D | C9: "," | D9: =unicode!A10 -> ㄍ | E9: " | F9: ,,"ai@indexbox.com","1","GB2312","注音","unicode",NULL,NULL | G9: =A9&B9&C9&D9&E9&F9 -> ,"310D","ㄍ",,"ai@indexbox.com","1","GB2312","注音","unicode",NULL,NULL
A10: ," | B10: =unicode!B11 -> 310E | C10: "," | D10: =unicode!A11 -> ㄎ | E10: " | F10: ,,"ai@indexbox.com","1","GB2312","注音","unicode",NULL,NULL | G10: =A10&B10&C10&D10&E10&F10 -> ,"310E","ㄎ",,"ai@indexbox.com","1","GB2312","注音","unicode",NULL,NULL
A11: ," | B11: =unicode!B12 -> 310F | C11: "," | D11: =unicode!A12 -> ㄏ | E11: " | F11: ,,"ai@indexbox.com","1","GB2312","注音","unicode",NULL,NULL | G11: =A11&B11&C11&D11&E11&F11 -> ,"310F","ㄏ",,"ai@indexbox.com","1","GB2312","注音","unicode",NULL,NULL
A12: ," | B12: =unicode!B13 -> 3110 | C12: "," | D12: =unicode!A13 -> ㄐ | E12: " | F12: ,,"ai@indexbox.com","1","GB2312","注音","unicode",NULL,NULL | G12: =A12&B12&C12&D12&E12&F12 -> ,"3110","ㄐ",,"ai@indexbox.com","1","GB2312","注音","unicode",NULL,NULL
... A37: ," | B37: =unicode!B38 -> 3129 | C37: "," | D37: =unicode!A38 -> ㄩ | E37: " | F37: ,,"ai@indexbox.com","1","GB2312","注音","unicode",NULL,NULL | G37: =A37&B37&C37&D37&E37&F37 -> ,"3129","ㄩ",,"ai@indexbox.com","1","GB2312","注音","unicode",NULL,NULL
